<?xml version="1.0" ?>
<sdf version="1.6">
  <model name="conveyor_belt_in">

    <model name="conveyor_belt_in_fixed">
      <static>true</static>
      <!-- Hard Coded to match the ends of the fixed && moving segments -->
      <pose>0 -0.45 0 0 0 -1.57079</pose>
      <link name="belt">
        <pose>-5 0 0 0 0 0</pose>
        <visual name="belt_visual">
          <geometry>
            <box>
              <size>10.00 0.50 0.10</size>
            </box>
          </geometry>
        </visual>
      </link>
    </model>

    <model name="conveyor_belt_in_moving">
      <static>false</static>
      <pose>0 0 0 0 0 -1.57079</pose>
      <link name="belt">
        <pose>-5 0 0 0 0 0</pose>

        <!--Uncomment for debugging -->
        <!-- <visual name="belt_visual">
          <geometry>
            <box>
              <size>10.00 0.50 0.10</size>
            </box>
          </geometry>
        </visual> -->

        <collision name="belt_collision">
          <geometry>
            <box>
              <size>10.00 0.50 0.10</size>
            </box>
          </geometry>
        </collision>
      </link>
    </model>

    <joint name="belt_joint" type="prismatic">
      <parent>conveyor_belt_in_fixed::belt</parent>
      <child>conveyor_belt_in_moving::belt</child>
      <axis>
        <xyz>1 0 0</xyz>
        <limit>
          <lower>0</lower>
          <upper>1.0</upper>
        </limit>
      </axis>
    </joint>

    <plugin name="conveyor_belt_plugin" filename="libROSConveyorBeltPlugin.so">
      <robot_namespace>/ur5_t2_4230</robot_namespace>
      <topic>conveyor/control/in</topic>
      <link>conveyor_belt_in::conveyor_belt_in_moving::belt</link>
      <power>100.0</power>
      <!-- <max_belt_linear_vel>2.0</max_belt_linear_vel> -->

    </plugin>

  </model>
</sdf>