<?xml version="1.0" ?>
<sdf version="1.6">
  <model name="conveyor_belt_out">

    <model name="conveyor_belt_out_fixed">
      <static>true</static>
      <!-- Hard Coded to match the ends of the fixed && moving segments -->
      <pose>0 -0.45 0 0 0 -1.57079</pose>
      <link name="belt">
        <pose>-2 0 0 0 0 0</pose>
        <visual name="belt_visual">

          <geometry>
            <box>
              <size>4.00 0.50 0.20</size>
            </box>
          </geometry>

          <material>
            <script>
              <uri>file://media/materials/scripts/gazebo.material</uri>
              <name>Gazebo/DarkGrey</name>
            </script>
          </material>

        </visual>
      </link>
    </model>

    <model name="conveyor_belt_out_moving">
      <static>false</static>
      <pose>0 0 0 0 0 -1.57079</pose>
      <link name="belt">
        <pose>-2 0 0 0 0 0</pose>

        <!--Uncomment for debugging -->
        <!-- <visual name="belt_visual">
          <geometry>
            <box>
              <size>4.00 0.50 0.20</size>
            </box>
          </geometry>
        </visual> -->

        <collision name="belt_collision">
          <geometry>
            <box>
              <size>4.00 0.50 0.20</size>
            </box>
          </geometry>
        </collision>
      </link>
    </model>

    <joint name="belt_joint" type="prismatic">
      <parent>conveyor_belt_out_fixed::belt</parent>
      <child>conveyor_belt_out_moving::belt</child>
      <axis>
        <xyz>1 0 0</xyz>
        <limit>
          <lower>0.00</lower>
          <upper>1.00</upper>
        </limit>
      </axis>
    </joint>

    <plugin name="conveyor_belt_plugin" filename="libROSConveyorBeltPlugin.so">
      <robot_namespace>/ur5_t2_4230</robot_namespace>
      <topic>conveyor/control/out</topic>
      <link>conveyor_belt_out::conveyor_belt_out_moving::belt</link>
      <power>50.0</power>
    </plugin>

  </model>
</sdf>