<?xml version="1.0" ?>
<sdf version="1.6">
   <model name="conveyor_belt">

     <model name="conveyor_belt_1">
       <static>true</static>
       <pose>0 0 0 0 0 -1.57079</pose>
       <link name="belt">
         <pose>-5 0 0 0 0 0</pose>
       </link>
     </model>

     <model name="conveyor_belt_2">
       <static>false</static>
       <pose>0 0 0 0 0 -1.57079</pose>
       <link name="belt">
         <pose>-5 0 0 0 0 0</pose>
         <inertial>
           <inertia>
             <ixx>3.8185</ixx>
             <ixy>0</ixy>
             <ixz>0</ixz>
             <iyy>1781.5</iyy>
             <iyz>0</iyz>
             <izz>1784.72</izz>
           </inertia>
           <mass>100</mass>
         </inertial>
         <!--Uncomment for debugging -->

         <visual name="belt_visual">
           <geometry>
             <box>
               <size>10.00 0.50 0.10</size>
             </box>
           </geometry>
         </visual>

         <collision name="belt_collision">
           <geometry>
             <box>
               <size>10.00 0.50 0.10</size>
             </box>
           </geometry>
           <surface>
             <friction>
               <ode>
                 <mu>1.0</mu>
                 <mu2>1.0</mu2>
               </ode>
               <torsional>
                 <coefficient>1000.0</coefficient>
                 <patch_radius>0.1</patch_radius>
               </torsional>
             </friction>
           </surface>
         </collision>
       </link>
     </model>

     <joint name="belt_joint" type="prismatic">
       <parent>conveyor_belt_1::belt</parent>
       <child>conveyor_belt_2::belt</child>
       <axis>
         <xyz>1 0 0</xyz>
         <limit>
           <lower>0</lower>
           <upper>1.0</upper>
         </limit>
       </axis>
     </joint>

     <plugin name="conveyor_belt_plugin" filename="libROSConveyorBeltPlugin.so">
       <robot_namespace>/ur5_t2_4230</robot_namespace>
       <link>conveyor_belt::conveyor_belt_2::belt</link>
       <power>100.0</power>
       <!-- <max_belt_linear_vel>2.0</max_belt_linear_vel> -->
     </plugin>
   </model>
</sdf>